<?xml version="1.0" ?>
<robot xmlns:xacro="http://www.ros.org/wiki/xacro">

  <xacro:macro name="parallel_fingers" params="prefix">

    <link name="${prefix}palm">
      <visual>
	<origin rpy="0.0 0.0 0.0" xyz="0.0 0.0 0.0"/>
	<geometry>
	  <mesh filename="package://robots_description/meshes/palm.dae"/>
	</geometry>
      </visual>
      <collision>
	<origin rpy="0.0 0.0 0.0" xyz="0.0 0.0 0.020"/>
	<geometry>
	  <cylinder length="0.04" radius="0.04"/>
	</geometry>
      </collision>
    </link>

    <link name="${prefix}right_finger">
      <visual>
	<origin rpy="${-pi} ${pi / 2.0} 0.0" xyz="0.0 0.0 0.0"/>
	<geometry>
	  <mesh filename="package://robots_description/meshes/finger.dae"/>
	</geometry>
      </visual>
      <collision>
	<origin rpy="${-pi} ${pi / 2.0} 0.0" xyz="0.0 -0.030 0.0"/>
	<geometry>
	  <box size="0.010 0.060 0.040"/>
	</geometry>
      </collision>
    </link>

    <link name="${prefix}left_finger">
      <visual>
	<origin rpy="${pi} ${-pi / 2.0} 0.0" xyz="0.0 0.0 0.0"/>
	<geometry>
	  <mesh filename="package://robots_description/meshes/finger.dae"/>
	</geometry>
      </visual>
      <collision>
	<origin rpy="${-pi} ${-pi / 2.0} 0.0" xyz="0.0 -0.030 0.0"/>
	<geometry>
	  <box size="0.010 0.060 0.040"/>
	</geometry>
      </collision>
    </link>

    <joint name="${prefix}palm-right_finger" type="prismatic">
      <parent link="${prefix}palm"/>
      <child link="${prefix}right_finger"/>
      <origin rpy="${pi / 2.0} 0.0 ${pi / 2.0}" xyz="0.005 0.0 0.0"/>
      <axis xyz="0 0 1"/>
      <limit effort="10.0" lower="0.0" upper="0.020" velocity="0.0"/>
    </joint>

    <joint name="${prefix}palm-left_finger" type="prismatic">
      <parent link="${prefix}palm"/>
      <child link="${prefix}left_finger"/>
      <mimic joint="${prefix}palm-right_finger" multiplier="1.0" offset="0.0"/>
      <origin rpy="${pi / 2.0} 0.0 ${-pi / 2.0}" xyz="-0.005 0.0 0.0"/>
      <axis xyz="0 0 1"/>
      <limit effort="10.0" lower="0.0" upper="0.020" velocity="0.0"/>
    </joint>

  </xacro:macro>

</robot>
