<?xml version="1.0" ?>
<!-- =================================================================================== -->
<!-- |    This document was autogenerated by xacro from robot_5r.urdf.xacro            | -->
<!-- |    EDITING THIS FILE BY HAND IS NOT RECOMMENDED                                 | -->
<!-- =================================================================================== -->
<robot name="robot_5r">
  <link name="base_link">
    <visual>
      <origin rpy="0.0 0.0 0.0" xyz="0.0 0.0 0.010"/>
      <geometry>
        <cylinder length="0.020" radius="0.150"/>
      </geometry>
    </visual>
    <collision>
      <origin rpy="0.0 0.0 0.0" xyz="0.0 0.0 0.010"/>
      <geometry>
        <cylinder length="0.020" radius="0.150"/>
      </geometry>
    </collision>
  </link>
  <link name="shoulder">
    <visual>
      <origin rpy="0.0 0.0 0.0" xyz="0.0 0.0 0.0"/>
      <geometry>
        <mesh filename="package://robots_description/meshes/shoulder.dae"/>
      </geometry>
    </visual>
    <collision>
      <origin rpy="0.0 0.0 0.0" xyz="0.0 0.0 0.050"/>
      <geometry>
        <cylinder length="0.100" radius="0.050"/>
      </geometry>
    </collision>
  </link>
  <link name="arm">
    <visual>
      <origin rpy="-1.5707963267948966 0.0 0.0" xyz="0.0 -0.045 0.06"/>
      <geometry>
        <mesh filename="package://robots_description/meshes/arm.dae"/>
      </geometry>
    </visual>
    <collision>
      <origin rpy="-1.5707963267948966 0.0 0.0" xyz="0.0 0.355 0.0523359"/>
      <geometry>
        <box size="0.090 0.105 0.800"/>
      </geometry>
    </collision>
  </link>
  <link name="forearm">
    <visual>
      <origin rpy="-1.5707963267948966 0.0 3.141592653589793" xyz="0.0 0.045 0.060"/>
      <geometry>
        <mesh filename="package://robots_description/meshes/arm.dae"/>
      </geometry>
    </visual>
    <collision>
      <origin rpy="-1.5707963267948966 0.0 3.141592653589793" xyz="0.0 -0.355 0.0523359"/>
      <geometry>
        <box size="0.090 0.105 0.800"/>
      </geometry>
    </collision>
  </link>
  <link name="hand">
    <visual>
      <origin rpy="0.0 0.0 0.0" xyz="0.0 0.0 0.0"/>
      <geometry>
        <mesh filename="package://robots_description/meshes/hand.dae"/>
      </geometry>
    </visual>
    <collision>
      <origin rpy="0.0 0.0 0.0" xyz="0.0 -0.0101 0.050"/>
      <geometry>
        <box size="0.080 0.100 0.100"/>
      </geometry>
    </collision>
  </link>
  <joint name="base-shoulder" type="revolute">
    <parent link="base_link"/>
    <child link="shoulder"/>
    <origin rpy="0.0 0.0 0.0" xyz="0.0 0.0 0.020"/>
    <axis xyz="0 0 1"/>
    <limit effort="20.0" lower="-3.141592653589793" upper="3.141592653589793" velocity="1.0"/>
  </joint>
  <joint name="shoulder-arm" type="revolute">
    <parent link="shoulder"/>
    <child link="arm"/>
    <origin rpy="1.5707963267948966 0.0 0.0" xyz="0.0 -0.060 0.055"/>
    <axis xyz="0 0 1"/>
    <limit effort="50.0" lower="-1.5707963267948966" upper="1.5707963267948966" velocity="1.0"/>
  </joint>
  <joint name="arm-forearm" type="revolute">
    <parent link="arm"/>
    <child link="forearm"/>
    <origin rpy="3.141592653589793 0.0 0.0" xyz="0.0 0.700 0.0"/>
    <axis xyz="0 0 1"/>
    <limit effort="25.0" lower="-2.792526803190927" upper="2.792526803190927" velocity="1.0"/>
  </joint>
  <joint name="forearm-hand" type="revolute">
    <parent link="forearm"/>
    <child link="hand"/>
    <origin rpy="3.141592653589793 0.0 3.141592653589793" xyz="0.0 -0.700 0.0"/>
    <axis xyz="0 0 1"/>
    <limit effort="10.0" lower="-3.141592653589793" upper="3.141592653589793" velocity="1.0"/>
  </joint>
</robot>
